Workbook
Name a: WACC!a
Name a: [0]!a
Name AboutCompGraph: WACC!AboutCompGraph
Name AboutCompGraph: [0]!AboutCompGraph
Name acq_pv: #REF!
Name Acq15Day: #REF!
Name Acq30Day: #REF!
Name Acq60Day: #REF!
Name Acq90Day: #REF!
Name AcqDate: #REF!
Name AcqPrice: #REF!
Name AcqQ: #REF!
Name AcqResearch: #REF!
Name AcqYest: #REF!
Name Annotate_Area: #REF!
Name AnnotateClearSet: #REF!
Name AnnotateNoteClear: #REF!
Name AnnotateNoteReturn: #REF!
Name AnnotateNoteSet: #REF!
Name AnnotateStart: #REF!
Name avgBlock: #REF!
Name AvgPrice: #REF!
Name AxesFormat: WACC!AxesFormat
Name AxesFormat: [0]!AxesFormat
Name BackFromCompanySelector: WACC!BackFromCompanySelector
Name BackFromCompanySelector: [0]!BackFromCompanySelector
Name BackFromItemSelect: WACC!BackFromItemSelect
Name BackFromItemSelect: [0]!BackFromItemSelect
Name BalanceSheet: #REF!
Name bDown: WACC!bDown
Name bDown: [0]!bDown
Name BeginDate: #REF!
Name BeginDate: #REF!
Name BeginDateSet: #REF!
Name BeginReturn: #REF!
Name BlackWhiteNote: #REF!
Name BlackWhiteSet: #REF!
Name bLeft: WACC!bLeft
Name bLeft: [0]!bLeft
Name bRight: WACC!bRight
Name bRight: [0]!bRight
Name bUp: WACC!bUp
Name bUp: [0]!bUp
Name Cellsdown: #REF!
Name Cellsdown: #REF!
Name ChangeSize: WACC!ChangeSize
Name ChangeSize: [0]!ChangeSize
Name ChartOptions: WACC!ChartOptions
Name ChartOptions: [0]!ChartOptions
Name ChartType: #REF!
Name ChartType: #REF!
Name ChartTypeChange: WACC!ChartTypeChange
Name ChartTypeChange: [0]!ChartTypeChange
Name cleanup: #REF!
Name cleanup: #REF!
Name ClearCompList: WACC!ClearCompList
Name ClearCompList: [0]!ClearCompList
Name ClipBoardRange: #REF!
Name ClipBoardRange: #REF!
Name ColorNoteReturn: #REF!

Sheet Cover
A1: WD-40 Financial Model
B3: PAGE
A4: Assumptions | B4: 1
A5: Debt | B5: =B4+1 -> 2
A6: Calcs | B6: =B5+1 -> 3
A7: Income Statement | B7: =B6+1 -> 4
A8: Balance Sheet | B8: =B7+1 -> 5
A9: WACC | B9: =B8+1 -> 6
A10: Cash Flow Statement | B10: =B9+1 -> 7
A11: Trading Comps | B11: =B10+1 -> 8
A12: Transaction Comps | B12: =B11+1 -> 9
A13: AVP | B13: =B12+1 -> 10
A14: Summary | B14: =B13+1 -> 11

Sheet Balance Sheet HISTORICAL
A1: WD-40 Balance Sheet
B2: (USD in thousands, except per share data)
C4: 41882 | D4: 42247 | E4: 42613 | F4: 42978 | G4: 43343 | H4: 43708 | I4: 44074 | J4: 44439 | K4: 44804 | L4: 45169 | M4: 45535
B5: Assets:
B6: Cash and cash equivalents | C6: 57803 | D6: 53896 | E6: 50891 | F6: 37082 | G6: 48866 | H6: 27233 | I6: 56462 | J6: 85961 | K6: 37843 | L6: 48143 | M6: 46699
B7: Short-term investments | C7: 45050 | D7: 48603 | E7: 57633 | F7: 80166 | G7: 219 | H7: 0 | I7: 0 | J7: 0 | K7: 0 | L7: 0 | M7: 0
B8: Trade and other accounts receivable, net | C8: 63618 | D8: 58750 | E8: 64680 | F8: 64259 | G8: 69025 | H8: 72864 | I8: 80672 | J8: 89558 | K8: 89930 | L8: 98039 | M8: 117493
B9: Inventories | C9: 34989 | D9: 32052 | E9: 31793 | F9: 35340 | G9: 36536 | H9: 40682 | I9: 41264 | J9: 55752 | K9: 104101 | L9: 86522 | M9: 79088
B10: Current deferred tax assets, net | C10: 5855 | D10: 5824 | E10: 0 | F10: 0 | G10: 0 | H10: 0 | I10: 0 | J10: 0 | K10: 0 | L10: 0 | M10: 0
B11: Other current assets | C11: 8339 | D11: 6127 | E11: 4475 | F11: 8007 | G11: 13337 | H11: 7216 | I11: 6756 | J11: 9948 | K11: 17766 | L11: 15821 | M11: 12161
A12: * | B12: Total current assets | C12: =SUM(C6:C11) -> 215654 | D12: =SUM(D6:D11) -> 205252 | E12: =SUM(E6:E11) -> 209472 | F12: =SUM(F6:F11) -> 224854 | G12: =SUM(G6:G11) -> 167983 | H12: =SUM(H6:H11) -> 147995 | I12: =SUM(I6:I11) -> 185154 | J12: =SUM(J6:J11) -> 241219 | ... M12: =SUM(M6:M11) -> 255441
B13: Property and equipment, net | C13: 9702 | D13: 11376 | E13: 11545 | F13: 29439 | G13: 36357 | H13: 45076 | I13: 60759 | J13: 70145 | K13: 65977 | L13: 66791 | M13: 62983 | P13: Beginning | Q13: Beg PP&E
B14: Goodwill | C14: 95499 | D14: 96409 | E14: 95649 | F14: 95597 | G14: 95621 | H14: 95347 | I14: 95731 | J14: 95869 | K14: 95180 | L14: 95505 | M14: 96985 | P14: Additions | Q14: + Capex
B15: Other intangible assets, net | C15: 23671 | D15: 22961 | E15: 19191 | F15: 16244 | G15: 13513 | H15: 10652 | I15: 8633 | J15: 7244 | K15: 5588 | L15: 4670 | M15: 6222 | P15: Subtractions | Q15: - Depreciation
B16: Right-of-use assets | C16: 0 | D16: 0 | E16: 0 | F16: 0 | G16: 0 | H16: 0 | I16: 8168 | J16: 8824 | K16: 7559 | L16: 7820 | M16: 11611 | P16: Ending | Q16: = Ending PP&E
B17: Deferred tax assets, net | C17: 0 | D17: 0 | E17: 621 | F17: 495 | G17: 511 | H17: 403 | I17: 464 | J17: 858 | K17: 679 | L17: 1201 | M17: 993
B18: Other assets | C18: 3154 | D18: 3259 | E18: 3190 | F18: 3088 | G18: 3074 | H18: 3189 | I18: 3728 | J18: 6044 | K18: 9672 | L18: 13454 | M18: 14804
A19: * | B19: Total assets | C19: =SUM(C12:C18) -> 347680 | D19: =SUM(D12:D18) -> 339257 | E19: =SUM(E12:E18) -> 339668 | F19: =SUM(F12:F18) -> 369717 | G19: =SUM(G12:G18) -> 317059 | H19: =SUM(H12:H18) -> 302662 | I19: =SUM(I12:I18) -> 362637 | J19: =SUM(J12:J18) -> 430203 | ... M19: =SUM(M12:M18) -> 449039
B21: Liabilities and Shareholders' Equity:
B22: Accounts payable | C22: 18031 | D22: 17128 | E22: 18690 | F22: 20898 | G22: 19115 | H22: 18727 | I22: 21676 | J22: 33499 | K22: 32852 | L22: 30826 | M22: 35960
B23: Accrued liabilities | C23: 18382 | D23: 15200 | E23: 15757 | F23: 18997 | G23: 26240 | H23: 18513 | I23: 21660 | J23: 25658 | K23: 27161 | L23: 30000 | M23: 31272
B24: Accrued payroll and related expenses | C24: 15969 | D24: 13357 | E24: 20866 | F24: 14222 | G24: 14823 | H24: 15301 | I24: 14767 | J24: 25662 | K24: 11583 | L24: 16722 | M24: 26055
B25: Revolving credit facility, current portion | C25: 98000 | D25: 0 | E25: 0 | F25: 20000 | G25: 22800 | H25: 20405 | I25: 0 | J25: 0 | K25: =39173-800 -> 38373 | L25: 10000 | M25: =8659-800 -> 7859 | N25: Debt schedule
B26: Short-term borrowings | C26: 0 | D26: 0 | E26: 0 | F26: 0 | G26: 800 | H26: 800 | I26: 800 | J26: 800 | K26: 800 | L26: 800 | M26: 800 | N26: Debt schedule
B27: Income taxes payable | C27: 1529 | D27: 2287 | E27: 3381 | F27: 1306 | G27: 2125 | H27: 844 | I27: 1213 | J27: 317 | K27: 51 | L27: 494 | M27: 1554
A28: * | B28: Total current liabilities | C28: =SUM(C22:C27) -> 151911 | D28: =SUM(D22:D27) -> 47972 | E28: =SUM(E22:E27) -> 58694 | F28: =SUM(F22:F27) -> 75423 | G28: =SUM(G22:G27) -> 85903 | H28: =SUM(H22:H27) -> 74590 | I28: =SUM(I22:I27) -> 60116 | J28: =SUM(J22:J27) -> 85936 | ... M28: =SUM(M22:M27) -> 103500
B29: Revolving credit facility | C29: 0 | D29: 108000 | E29: 122000 | F29: 134000 | G29: 44000 | H29: 42221 | I29: 95898 | J29: 46540 | K29: =77912-(39173-800) -> 39539 | L29: =52943-10000 -> 42943 | M29: =27836-7859 -> 19977 | N29: Debt schedule
B30: Long-term borrowings | C30: 0 | D30: 0 | E30: 0 | F30: 0 | G30: 18800 | H30: 18000 | I30: 17200 | J30: =(17200-800)+26000+26000 -> 68400 | K30: =(16400-800)+26000+26000 -> 67600 | L30: =(15600-800)+26000+26000 -> 66800 | M30: =(14800-800)+26000+26000 -> 66000 | N30: Debt schedule
B31: Deferred tax liabilities, net | C31: 24253 | D31: 23145 | E31: 16365 | F31: 18949 | G31: 11050 | H31: 11688 | I31: 11291 | J31: 10401 | K31: 10528 | L31: 10305 | M31: 9066
B32: Long-term operating lease liabilities | C32: 0 | D32: 0 | E32: 0 | F32: 0 | G32: 0 | H32: 0 | I32: 6520 | J32: 7062 | K32: 5999 | L32: 5832 | M32: 5904
B33: Other long-term liabilities | C33: 2101 | D33: 2282 | E33: 2214 | F33: 1958 | G33: 1817 | H33: 10688 | I33: 11299 | J33: 11482 | K33: 11185 | L33: 13066 | M33: 14066
A34: * | B34: Total liabilities | C34: =SUM(C28:C33) -> 178265 | D34: =SUM(D28:D33) -> 181399 | E34: =SUM(E28:E33) -> 199273 | F34: =SUM(F28:F33) -> 230330 | G34: =SUM(G28:G33) -> 161570 | H34: =SUM(H28:H33) -> 157187 | I34: =SUM(I28:I33) -> 202324 | J34: =SUM(J28:J33) -> 229821 | ... M34: =SUM(M28:M33) -> 218513
B36: Shareholders' equity:
B37: Common stock | C37: 19 | D37: 20 | E37: 20 | F37: 20 | G37: 20 | H37: 20 | I37: 20 | J37: 20 | K37: 20 | L37: 20 | M37: 20
B38: Additional paid-in capital | C38: 136212 | D38: 141651 | E38: 145936 | F38: 150692 | G38: 153469 | H38: 155132 | I38: 157850 | J38: 163737 | K38: 165973 | L38: 171546 | M38: 175642
B39: Retained earnings | C39: 237596 | D39: 260683 | E39: 289642 | F39: 315764 | G39: 351266 | H39: 374060 | I39: 398731 | J39: 430735 | K39: 456076 | L39: 477488 | M39: 499931
B40: Accumulated other comprehensive income (loss) | C40: 1103 | D40: -8722 | E40: -27298 | F40: -28075 | G40: -27636 | H40: -32482 | I40: -28208 | J40: -26030 | K40: -36209 | L40: -31206 | M40: -29268
B41: Common stock held in treasury, at cost | C41: -205515 | D41: -235774 | E41: -267905 | F41: -299014 | G41: -321630 | H41: -351255 | I41: -368080 | J41: -368080 | K41: -397236 | L41: -407670 | M41: -415799
A42: * | B42: Total stockholders’ equity | C42: =SUM(C37:C41) -> 169415 | D42: =SUM(D37:D41) -> 157858 | E42: =SUM(E37:E41) -> 140395 | F42: =SUM(F37:F41) -> 139387 | G42: =SUM(G37:G41) -> 155489 | H42: =SUM(H37:H41) -> 145475 | I42: =SUM(I37:I41) -> 160313 | J42: =SUM(J37:J41) -> 200382 | ... M42: =SUM(M37:M41) -> 230526
A44: * | B44: Total liabilities and stockholders’ equity | C44: =C34+C42 -> 347680 | D44: =D34+D42 -> 339257 | E44: =E34+E42 -> 339668 | F44: =F34+F42 -> 369717 | G44: =G34+G42 -> 317059 | H44: =H34+H42 -> 302662 | I44: =I34+I42 -> 362637 | J44: =J34+J42 -> 430203 | ... M44: =M34+M42 -> 449039
...

Sheet Assumptions
A1: WD-40 Assumptions
T2: Projected
B3: 42247 | C3: 42613 | D3: 42978 | E3: 43343 | F3: 43708 | G3: 44074 | H3: 44439 | I3: 44804 | J3: 45169 | K3: 45535 | M3: 10 yr AVG | N3: 5 yr AVG | O3: 3 yr AVG | Q3: DRIVER | S3: Rationale | T3: 45900 | U3: 46265 | V3: 46630 | W3: 46996 | X3: 47361
A4: Income Statement (non-debt items)
A5: Net sales (growth in sales) | B5: ='Income Statement'!D6/'Income Statement'!C6-1 -> -0.012655452 | C5: ='Income Statement'!E6/'Income Statement'!D6-1 -> 0.0066640222 | D5: ='Income Statement'!F6/'Income Statement'!E6-1 -> -0.00043081934 | E5: ='Income Statement'!G6/'Income Statement'!F6-1 -> 0.073617762 | F5: ='Income Statement'!H6/'Income Statement'!G6-1 -> 0.036306846 | G5: ='Income Statement'!I6/'Income Statement'!H6-1 -> -0.035082083 | H5: ='Income Statement'!J6/'Income Statement'!I6-1 -> 0.19488712 | I5: ='Income Statement'!K6/'Income Statement'!J6-1 -> 0.062918324 | ... K5: ='Income Statement'!M6/'Income Statement'!L6-1 -> 0.099211734 | M5: =AVERAGE(B5:K5) -> 0.046097001 | N5: =AVERAGE(G5:K5) -> 0.07149353 | O5: =AVERAGE(I5:K5) -> 0.065887537 | Q5: 0.07 | S5: Being conservative; Low End of 7-10% LT Segment guidance (pg. 21 of 58 - 1/10/25 Presentation) | T5: =Q5 -> 0.07 | U5: =T5 -> 0.07 | V5: =U5 -> 0.07 | W5: =V5 -> 0.07 | X5: =W5 -> 0.07
A6: Clean COGS (as % of sales) | B6: ='Income Statement'!D7/'Income Statement'!D6 -> 0.46501909 | C6: ='Income Statement'!E7/'Income Statement'!E6 -> 0.43149827 | D6: ='Income Statement'!F7/'Income Statement'!F6 -> 0.43183519 | E6: ='Income Statement'!G7/'Income Statement'!G6 -> 0.4414449 | F6: ='Income Statement'!H7/'Income Statement'!H6 -> 0.44418614 | G6: ='Income Statement'!I7/'Income Statement'!I6 -> 0.44594849 | H6: ='Income Statement'!J7/'Income Statement'!J6 -> 0.45274943 | I6: ='Income Statement'!K7/'Income Statement'!K6 -> 0.50028327 | ... K6: ='Income Statement'!M7/'Income Statement'!M6 -> 0.457743 | M6: =AVERAGE(B6:K6) -> 0.45519229 | N6: =AVERAGE(G6:K6) -> 0.46758785 | O6: =AVERAGE(I6:K6) -> 0.47974712 | Q6: 0.465 | S6: Steady increase 2016-2022, DECREASE 2022-2024; 55/30/25 Long-Term (WDFC Presentation pg. 39); 45-50% Guidance | T6: =Q6 -> 0.465 | U6: =T6 -> 0.465 | V6: =U6 -> 0.465 | W6: =V6 -> 0.465 | X6: =W6 -> 0.465
A7: Clean SG&A (as % of sales) | B7: ='Income Statement'!D9/'Income Statement'!D6 -> 0.28447185 | C7: ='Income Statement'!E9/'Income Statement'!E6 -> 0.30556796 | D7: ='Income Statement'!F9/'Income Statement'!F6 -> 0.29690759 | E7: ='Income Statement'!G9/'Income Statement'!G6 -> 0.29242729 | F7: ='Income Statement'!H9/'Income Statement'!H6 -> 0.28823148 | G7: ='Income Statement'!I9/'Income Statement'!I6 -> 0.29327423 | H7: ='Income Statement'!J9/'Income Statement'!J6 -> 0.29358592 | I7: ='Income Statement'!K9/'Income Statement'!K6 -> 0.2627039 | ... K7: ='Income Statement'!M9/'Income Statement'!M6 -> 0.30567018 | M7: =AVERAGE(B7:K7) -> 0.29058304 | N7: =AVERAGE(G7:K7) -> 0.28764484 | O7: =AVERAGE(I7:K7) -> 0.28378802 | Q7: 0.285 | S7: Steady decrease since 2016 (2024 uptick in NOTE); Being conservaitve; 55/30/25 rule (pg. 39 of 1/10/25 Presentation) | T7: =Q7 -> 0.285 | U7: =T7 -> 0.285 | V7: =U7 -> 0.285 | W7: =V7 -> 0.285 | X7: =W7 -> 0.285
A8: Advertising and sales promotion (as % of sales) | B8: ='Income Statement'!D10/'Income Statement'!D6 -> 0.060494513 | C8: ='Income Statement'!E10/'Income Statement'!E6 -> 0.05852313 | D8: ='Income Statement'!F10/'Income Statement'!F6 -> 0.053972868 | E8: ='Income Statement'!G10/'Income Statement'!G6 -> 0.054621828 | F8: ='Income Statement'!H10/'Income Statement'!H6 -> 0.055051376 | G8: ='Income Statement'!I10/'Income Statement'!I6 -> 0.052891324 | H8: ='Income Statement'!J10/'Income Statement'!J6 -> 0.057274092 | I8: ='Income Statement'!K10/'Income Statement'!K6 -> 0.052702286 | ... K8: ='Income Statement'!M10/'Income Statement'!M6 -> 0.057422061 | M8: =AVERAGE(B8:K8) -> 0.055657234 | N8: =AVERAGE(G8:K8) -> 0.054781724 | O8: =AVERAGE(I8:K8) -> 0.054581069 | Q8: 0.06 | S8: Declined 2015-2020, uptick in 2024; Mgmt guidance of 6% (pg. 46 of 1/10/25 presentation) | T8: =Q8 -> 0.06 | U8: =T8 -> 0.06 | V8: =U8 -> 0.06 | W8: =V8 -> 0.06 | X8: =W8 -> 0.06
A9: Amortization (as % of sales) | B9: ='Income Statement'!D13/'Income Statement'!D6 -> 0.0080364935 | C9: ='Income Statement'!E13/'Income Statement'!E6 -> 0.0078177949 | D9: ='Income Statement'!F13/'Income Statement'!F6 -> 0.0075662407 | E9: ='Income Statement'!G13/'Income Statement'!G6 -> 0.0072236719 | F9: ='Income Statement'!H13/'Income Statement'!H6 -> 0.0063918743 | G9: ='Income Statement'!I13/'Income Statement'!I6 -> 0.0054125112 | H9: ='Income Statement'!J13/'Income Statement'!J6 -> 0.0029685992 | I9: ='Income Statement'!K13/'Income Statement'!K6 -> 0.0027639644 | ... K9: ='Income Statement'!M13/'Income Statement'!M6 -> 0.0018728082 | M9: =AVERAGE(B9:K9) -> 0.0051924578 | N9: =AVERAGE(G9:K9) -> 0.0029777006 | O9: =AVERAGE(I9:K9) -> 0.0021691309 | Q9: 0.002 | S9: 3-yr average = 0.2%; Has been declining long-term; matching the trend; flat last 2 years | T9: =Q9 -> 0.002 | U9: =T9 -> 0.002 | V9: =U9 -> 0.002 | W9: =V9 -> 0.002 | X9: =W9 -> 0.002
A10: Other (expense) income, net (as % of sales) | B10: ='Income Statement'!D17/'Income Statement'!D6 -> -0.004387148 | C10: ='Income Statement'!E17/'Income Statement'!E6 -> 0.0064649171 | D10: ='Income Statement'!F17/'Income Statement'!F6 -> 0.0020682985 | E10: ='Income Statement'!G17/'Income Statement'!G6 -> 0.0008298288 | F10: ='Income Statement'!H17/'Income Statement'!H6 -> 0.0018282745 | G10: ='Income Statement'!I17/'Income Statement'!I6 -> 0.0015691631 | H10: ='Income Statement'!J17/'Income Statement'!J6 -> -5.7364236e-05 | I10: ='Income Statement'!K17/'Income Statement'!K6 -> -0.0011217763 | ... K10: ='Income Statement'!M17/'Income Statement'!M6 -> -0.0017441161 | M10: =AVERAGE(B10:K10) -> 0.00069800771 | N10: =AVERAGE(G10:K10) -> 3.5181225e-05 | O10: =AVERAGE(I10:K10) -> -0.00044529759 | Q10: 0 | S10: Inconsistent (4 negative / 6 positive) & ZERO will result in NO IMPACT | T10: =Q10 -> 0 | U10: =T10 -> 0 | V10: =U10 -> 0 | W10: =V10 -> 0 | X10: =W10 -> 0
A11: Provision for income taxes (Taxes / EBT) | B11: ='Income Statement'!D19/'Income Statement'!D18 -> 0.29001743 | C11: ='Income Statement'!E19/'Income Statement'!E18 -> 0.27697866 | D11: ='Income Statement'!F19/'Income Statement'!F18 -> 0.29069175 | E11: ='Income Statement'!G19/'Income Statement'!G18 -> 0.13252547 | F11: ='Income Statement'!H19/'Income Statement'!H18 -> 0.30781231 | G11: ='Income Statement'!I19/'Income Statement'!I18 -> 0.19605376 | H11: ='Income Statement'!J19/'Income Statement'!J18 -> 0.18809466 | I11: ='Income Statement'!K19/'Income Statement'!K18 -> 0.19949351 | ... K11: ='Income Statement'!M19/'Income Statement'!M18 -> 0.23892993 | M11: =AVERAGE(B11:K11) -> 0.23456952 | N11: =AVERAGE(G11:K11) -> 0.20953392 | O11: =AVERAGE(I11:K11) -> 0.22117373 | Q11: 0.23 | S11: U.S. Corp Tax Rate of 21% (since 2017 Tax Cuts and Jobs Act), but FOREIGN taxes increase this (see note) | T11: =Q11 -> 0.23 | U11: =T11 -> 0.23 | V11: =U11 -> 0.23 | W11: =V11 -> 0.23 | X11: =W11 -> 0.23
A13: Gross profit margin | B13: ='Income Statement'!D8/'Income Statement'!D6 -> 0.53498091 | C13: ='Income Statement'!E8/'Income Statement'!E6 -> 0.56850173 | D13: ='Income Statement'!F8/'Income Statement'!F6 -> 0.56816481 | E13: ='Income Statement'!G8/'Income Statement'!G6 -> 0.5585551 | F13: ='Income Statement'!H8/'Income Statement'!H6 -> 0.55581386 | G13: ='Income Statement'!I8/'Income Statement'!I6 -> 0.55405151 | H13: ='Income Statement'!J8/'Income Statement'!J6 -> 0.54725057 | I13: ='Income Statement'!K8/'Income Statement'!K6 -> 0.49971673 | ... K13: ='Income Statement'!M8/'Income Statement'!M6 -> 0.542257 | M13: =AVERAGE(B13:K13) -> 0.54480771 | N13: =AVERAGE(G13:K13) -> 0.53241215 | O13: =AVERAGE(I13:K13) -> 0.52025288 | S13: Gross margin increased until 2017; contracting since 2017-2022 due to Covid / Supply Chain / Inflation, but ticking up 2023-2024 (LT target 55/30/25 rule)
A14: EBITDA margin | B14: ='Income Statement'!D11/'Income Statement'!D6 -> 0.19001454 | C14: ='Income Statement'!E11/'Income Statement'!E6 -> 0.20441064 | D14: ='Income Statement'!F11/'Income Statement'!F6 -> 0.21728435 | E14: ='Income Statement'!G11/'Income Statement'!G6 -> 0.21150598 | F14: ='Income Statement'!H11/'Income Statement'!H6 -> 0.212531 | G14: ='Income Statement'!I11/'Income Statement'!I6 -> 0.20788596 | H14: ='Income Statement'!J11/'Income Statement'!J6 -> 0.19639056 | I14: ='Income Statement'!K11/'Income Statement'!K6 -> 0.18431055 | ... K14: ='Income Statement'!M11/'Income Statement'!M6 -> 0.17916475 | M14: =AVERAGE(B14:K14) -> 0.19856744 | N14: =AVERAGE(G14:K14) -> 0.18998558 | O14: =AVERAGE(I14:K14) -> 0.18188379 | S14: EBITDA margin increased until 2017; contracting since 2017 due to Covid / Supply Chain / Inflation (LT target 55/30/25 rule)
A15: EBIT margin | B15: ='Income Statement'!D14/'Income Statement'!D6 -> 0.1729208 | C15: ='Income Statement'!E14/'Income Statement'!E6 -> 0.18742743 | D15: ='Income Statement'!F14/'Income Statement'!F6 -> 0.19949488 | E15: ='Income Statement'!G14/'Income Statement'!G6 -> 0.19241257 | F15: ='Income Statement'!H14/'Income Statement'!H6 -> 0.19459549 | G15: ='Income Statement'!I14/'Income Statement'!I6 -> 0.18903397 | H15: ='Income Statement'!J14/'Income Statement'!J6 -> 0.18201058 | I15: ='Income Statement'!K14/'Income Statement'!K6 -> 0.16832427 | ... K15: ='Income Statement'!M14/'Income Statement'!M6 -> 0.16315275 | M15: =AVERAGE(B15:K15) -> 0.18163772 | N15: =AVERAGE(G15:K15) -> 0.17390521 | O15: =AVERAGE(I15:K15) -> 0.16616051 | S15: EBIT margin increased until 2017; contracting since 2017 due to Covid / Supply Chain / Inflation (should increase LT => 55/30/25 rule)
A16: Net income margin | B16: ='Income Statement'!D20/'Income Statement'!D6 -> 0.11849002 | C16: ='Income Statement'!E20/'Income Statement'!E6 -> 0.13825098 | D16: ='Income Statement'!F20/'Income Statement'!F6 -> 0.13910425 | E16: ='Income Statement'!G20/'Income Statement'!G6 -> 0.15963801 | F16: ='Income Statement'!H20/'Income Statement'!H6 -> 0.13206094 | G16: ='Income Statement'!I20/'Income Statement'!I6 -> 0.14861762 | H16: ='Income Statement'!J20/'Income Statement'!J6 -> 0.14387975 | I16: ='Income Statement'!K20/'Income Statement'!K6 -> 0.12977333 | ... K16: ='Income Statement'!M20/'Income Statement'!M6 -> 0.11792934 | M16: =AVERAGE(B16:K16) -> 0.13505779 | N16: =AVERAGE(G16:K16) -> 0.13260674 | O16: =AVERAGE(I16:K16) -> 0.12351211 | S16: Decreasing since 2018 higher tax rates due to expanding Int'l business has reduced net margin
A18: Shareholder Info
A19: Dividend Payout Ratio (Dividends / Net Income) | B19: =Calcs!D7/Calcs!D6 -> 0.48474569 | C19: =Calcs!E7/Calcs!E6 -> 0.44974158 | D19: =Calcs!F7/Calcs!F6 -> 0.50648026 | E19: =Calcs!G7/Calcs!G6 -> 0.4536533 | F19: =Calcs!H7/Calcs!H6 -> 0.58827002 | G19: =Calcs!I7/Calcs!I6 -> 0.59362543 | H19: =Calcs!J7/Calcs!J6 -> 0.54429082 | I19: =Calcs!K7/Calcs!K6 -> 0.62362429 | ... K19: =Calcs!M7/Calcs!M6 -> 0.67774683 | M19: =AVERAGE(B19:K19) -> 0.55977196 | N19: =AVERAGE(G19:K19) -> 0.62296574 | O19: =AVERAGE(I19:K19) -> 0.65897082 | Q19: 0.56 | S19: 10-yr avg (long-term); Investor Presentation, January 2025, pg. 41, "Annual dividends targeted at >50% of earnings" | T19: =Q19 -> 0.56 | U19: =T19 -> 0.56 | V19: =U19 -> 0.56 | W19: =V19 -> 0.56 | X19: =W19 -> 0.56
A21: Balance Sheet (Current Assets)
A22: Cash & ST Investments (REQUIRED) as % of sales | B22: =SUM('Balance Sheet HISTORICAL'!D6:D7)/'Income Statement'!D6 -> 0.27105381 | C22: =SUM('Balance Sheet HISTORICAL'!E6:E7)/'Income Statement'!E6 -> 0.28508682 | D22: =SUM('Balance Sheet HISTORICAL'!F6:F7)/'Income Statement'!F6 -> 0.30813706 | E22: =SUM('Balance Sheet HISTORICAL'!G6:G7)/'Income Statement'!G6 -> 0.12015382 | F22: =SUM('Balance Sheet HISTORICAL'!H6:H7)/'Income Statement'!H6 -> 0.064327389 | G22: =SUM('Balance Sheet HISTORICAL'!I6:I7)/'Income Statement'!I6 -> 0.13821855 | H22: =SUM('Balance Sheet HISTORICAL'!J6:J7)/'Income Statement'!J6 -> 0.17611025 | I22: =SUM('Balance Sheet HISTORICAL'!K6:K7)/'Income Statement'!K6 -> 0.072940519 | ... K22: =SUM('Balance Sheet HISTORICAL'!M6:M7)/'Income Statement'!M6 -> 0.079076194 | M22: =AVERAGE(B22:K22) -> 0.16047136 | N22: =AVERAGE(G22:K22) -> 0.11119095 | O22: =AVERAGE(I22:K22) -> 0.080541977 | Q22: 0.081 | S22: Downward trend long-term with an uptick in 2021 due to Covid so, went with the 3-yr avg, flat last 3 years | T22: =Q22 -> 0.081 | U22: =T22 -> 0.081 | V22: =U22 -> 0.081 | W22: =V22 -> 0.081 | X22: =W22 -> 0.081
A23: Accounts receivable, net as % of sales | B23: ='Balance Sheet HISTORICAL'!D8/'Income Statement'!D6 -> 0.15536163 | C23: ='Balance Sheet HISTORICAL'!E8/'Income Statement'!E6 -> 0.16991095 | D23: ='Balance Sheet HISTORICAL'!F8/'Income Statement'!F6 -> 0.16887776 | E23: ='Balance Sheet HISTORICAL'!G8/'Income Statement'!G6 -> 0.1689644 | F23: ='Balance Sheet HISTORICAL'!H8/'Income Statement'!H6 -> 0.17211291 | G23: ='Balance Sheet HISTORICAL'!I8/'Income Statement'!I6 -> 0.19748444 | H23: ='Balance Sheet HISTORICAL'!J8/'Income Statement'!J6 -> 0.18347951 | I23: ='Balance Sheet HISTORICAL'!K8/'Income Statement'!K6 -> 0.17333565 | ... K23: ='Balance Sheet HISTORICAL'!M8/'Income Statement'!M6 -> 0.19895285 | M23: =AVERAGE(B23:K23) -> 0.17709614 | N23: =AVERAGE(G23:K23) -> 0.18714675 | O23: =AVERAGE(I23:K23) -> 0.18492327 | Q23: 0.2 | S23: Avg. ex-Covid is 17.4%, average since Covid is 18.5% and on an upward trend so, I went with 20% | T23: =Q23 -> 0.2 | U23: =T23 -> 0.2 | V23: =U23 -> 0.2 | W23: =V23 -> 0.2 | X23: =W23 -> 0.2
A24: Inventories as % of COGS | B24: ='Balance Sheet HISTORICAL'!D9/'Income Statement'!D7 -> 0.18227212 | C24: ='Balance Sheet HISTORICAL'!E9/'Income Statement'!E7 -> 0.19355473 | D24: ='Balance Sheet HISTORICAL'!F9/'Income Statement'!F7 -> 0.21507355 | E24: ='Balance Sheet HISTORICAL'!G9/'Income Statement'!G7 -> 0.20259713 | F24: ='Balance Sheet HISTORICAL'!H9/'Income Statement'!H7 -> 0.21634045 | G24: ='Balance Sheet HISTORICAL'!I9/'Income Statement'!I7 -> 0.22651486 | H24: ='Balance Sheet HISTORICAL'!J9/'Income Statement'!J7 -> 0.25228169 | I24: ='Balance Sheet HISTORICAL'!K9/'Income Statement'!K7 -> 0.40107188 | ... K24: ='Balance Sheet HISTORICAL'!M9/'Income Statement'!M7 -> 0.29256816 | M24: =AVERAGE(B24:K24) -> 0.25169369 | N24: =AVERAGE(G24:K24) -> 0.30141979 | O24: =AVERAGE(I24:K24) -> 0.34276746 | Q24: 0.25 | S24: Pre-Covid avg. is 19.9%; Covid to today avg. is 33.7%; likely to be higher moving forward but not as high as recently, went with 25% | T24: =Q24 -> 0.25 | U24: =T24 -> 0.25 | V24: =U24 -> 0.25 | W24: =V24 -> 0.25 | X24: =W24 -> 0.25
A25: Other current assets as % of sales | B25: ='Balance Sheet HISTORICAL'!D11/'Income Statement'!D6 -> 0.016202565 | C25: ='Balance Sheet HISTORICAL'!E11/'Income Statement'!E6 -> 0.011755589 | D25: ='Balance Sheet HISTORICAL'!F11/'Income Statement'!F6 -> 0.021043032 | E25: ='Balance Sheet HISTORICAL'!G11/'Income Statement'!G6 -> 0.032647276 | F25: ='Balance Sheet HISTORICAL'!H11/'Income Statement'!H6 -> 0.017044998 | G25: ='Balance Sheet HISTORICAL'!I11/'Income Statement'!I6 -> 0.016538637 | H25: ='Balance Sheet HISTORICAL'!J11/'Income Statement'!J6 -> 0.020380694 | I25: ='Balance Sheet HISTORICAL'!K11/'Income Statement'!K6 -> 0.03424309 | ... K25: ='Balance Sheet HISTORICAL'!M11/'Income Statement'!M6 -> 0.020592424 | M25: =AVERAGE(B25:K25) -> 0.021989615 | N25: =AVERAGE(G25:K25) -> 0.024240537 | O25: =AVERAGE(I25:K25) -> 0.028094452 | Q25: 0.02 | S25: Pre-Covid avg. is 2.0%; Covid to today avg. is 2.8%%; on a downward trend so, went with 2% matching historical average | T25: =Q25 -> 0.02 | U25: =T25 -> 0.02 | V25: =U25 -> 0.02 | W25: =V25 -> 0.02 | X25: =W25 -> 0.02
A27: Balance Sheet (Non-Current Assets)
A28: Capital Expenditures (as % of sales) | B28: =Calcs!D20/'Income Statement'!D6 -> 0.015295518 | C28: =Calcs!E20/'Income Statement'!E6 -> 0.011437728 | D28: =Calcs!F20/'Income Statement'!F6 -> 0.052955801 | E28: =Calcs!G20/'Income Statement'!G6 -> 0.030245913 | F28: =Calcs!H20/'Income Statement'!H6 -> 0.031373568 | G28: =Calcs!I20/'Income Statement'!I6 -> 0.047263389 | H28: =Calcs!J20/'Income Statement'!J6 -> 0.030851715 | I28: =Calcs!K20/'Income Statement'!K6 -> 0.016003624 | ... K28: =Calcs!M20/'Income Statement'!M6 -> 0.0071220898 | M28: =AVERAGE(B28:K28) -> 0.025533843 | N28: =AVERAGE(G28:K28) -> 0.022805981 | O28: =AVERAGE(I28:K28) -> 0.0119716 | Q28: 0.02 | S28: Mgmt guidance, January 2025, pg. 41 "Maintenance CAPEX of 1-2% of net sales per fiscal year" (Avg. ex 2017-2021 = 1.3%) | T28: =Q28 -> 0.02 | U28: =T28 -> 0.02 | V28: =U28 -> 0.02 | W28: =V28 -> 0.02 | X28: =W28 -> 0.02
A29: Depreciation (as % of sales) | B29: =Calcs!D26/'Income Statement'!D6 -> 0.0090572524 | C29: =Calcs!E26/'Income Statement'!E6 -> 0.0091654189 | D29: =Calcs!F26/'Income Statement'!F6 -> 0.010223229 | E29: =Calcs!G26/'Income Statement'!G6 -> 0.011869734 | F29: =Calcs!H26/'Income Statement'!H6 -> 0.01154364 | G29: =Calcs!I26/'Income Statement'!I6 -> 0.013439478 | H29: =Calcs!J26/'Income Statement'!J6 -> 0.011411386 | I29: =Calcs!K26/'Income Statement'!K6 -> 0.013222312 | ... K29: =Calcs!M26/'Income Statement'!M6 -> 0.014139194 | M29: =AVERAGE(B29:K29) -> 0.011737259 | N29: =AVERAGE(G29:K29) -> 0.013102663 | O29: =AVERAGE(I29:K29) -> 0.013554151 | Q29: 0.014 | S29: Depreciation increasing after Capex build due to Real Estate purchase and development 2017-2021; went with 3-yr avg. | T29: =Q29 -> 0.014 | U29: =T29 -> 0.014 | V29: =U29 -> 0.014 | W29: =V29 -> 0.014 | X29: =W29 -> 0.014
A30: GOODWILL (ACTUAL) | B30: ='Balance Sheet HISTORICAL'!D14 -> 96409 | C30: ='Balance Sheet HISTORICAL'!E14 -> 95649 | D30: ='Balance Sheet HISTORICAL'!F14 -> 95597 | E30: ='Balance Sheet HISTORICAL'!G14 -> 95621 | F30: ='Balance Sheet HISTORICAL'!H14 -> 95347 | G30: ='Balance Sheet HISTORICAL'!I14 -> 95731 | H30: ='Balance Sheet HISTORICAL'!J14 -> 95869 | I30: ='Balance Sheet HISTORICAL'!K14 -> 95180 | ... K30: ='Balance Sheet HISTORICAL'!M14 -> 96985 | M30: =NA() -> #N/A | N30: =NA() -> #N/A | O30: =NA() -> #N/A | Q30: =K30 -> 96985 | S30: KEEP FLAT (SAME) = NO Cash Flow | T30: =Q30 -> 96985 | U30: =T30 -> 96985 | V30: =U30 -> 96985 | W30: =V30 -> 96985 | X30: =W30 -> 96985
A31: NEW Intangibles (NEW PURCHASES) | B31: =Calcs!D14 -> 2329 | C31: =Calcs!E14 -> -794 | D31: =Calcs!F14 -> -68 | E31: =Calcs!G14 -> 220 | F31: =Calcs!H14 -> -155 | G31: =Calcs!I14 -> 192 | H31: =Calcs!J14 -> 60 | I31: =Calcs!K14 -> -222 | ... K31: =Calcs!M14 -> 2658 | M31: =NA() -> #N/A | N31: =NA() -> #N/A | O31: =NA() -> #N/A | Q31: 0 | S31: Make ZERO (no assumption of increasing intangibles) | T31: =Q31 -> 0 | U31: =T31 -> 0 | V31: =U31 -> 0 | W31: =V31 -> 0 | X31: =W31 -> 0
A32: Right-of-use assets (ACTUAL) | B32: ='Balance Sheet HISTORICAL'!D16 -> 0 | C32: ='Balance Sheet HISTORICAL'!E16 -> 0 | D32: ='Balance Sheet HISTORICAL'!F16 -> 0 | E32: ='Balance Sheet HISTORICAL'!G16 -> 0 | F32: ='Balance Sheet HISTORICAL'!H16 -> 0 | G32: ='Balance Sheet HISTORICAL'!I16 -> 8168 | H32: ='Balance Sheet HISTORICAL'!J16 -> 8824 | I32: ='Balance Sheet HISTORICAL'!K16 -> 7559 | ... K32: ='Balance Sheet HISTORICAL'!M16 -> 11611 | M32: =NA() -> #N/A | N32: =NA() -> #N/A | O32: =NA() -> #N/A | Q32: =K32 -> 11611 | S32: KEEP FLAT (SAME) = NO Cash Flow | T32: =Q32 -> 11611 | U32: =T32 -> 11611 | V32: =U32 -> 11611 | W32: =V32 -> 11611 | X32: =W32 -> 11611
A33: Deferred tax assets, net (ACTUAL) | B33: ='Balance Sheet HISTORICAL'!D17 -> 0 | C33: ='Balance Sheet HISTORICAL'!E17 -> 621 | D33: ='Balance Sheet HISTORICAL'!F17 -> 495 | E33: ='Balance Sheet HISTORICAL'!G17 -> 511 | F33: ='Balance Sheet HISTORICAL'!H17 -> 403 | G33: ='Balance Sheet HISTORICAL'!I17 -> 464 | H33: ='Balance Sheet HISTORICAL'!J17 -> 858 | I33: ='Balance Sheet HISTORICAL'!K17 -> 679 | ... K33: ='Balance Sheet HISTORICAL'!M17 -> 993 | M33: =NA() -> #N/A | N33: =NA() -> #N/A | O33: =NA() -> #N/A | Q33: =K33 -> 993 | S33: KEEP FLAT (SAME) = NO Cash Flow | T33: =Q33 -> 993 | U33: =T33 -> 993 | V33: =U33 -> 993 | W33: =V33 -> 993 | X33: =W33 -> 993
A34: Other assets as % of sales | B34: ='Balance Sheet HISTORICAL'!D18/'Income Statement'!D6 -> 0.0086182732 | C34: ='Balance Sheet HISTORICAL'!E18/'Income Statement'!E6 -> 0.0083799616 | D34: ='Balance Sheet HISTORICAL'!F18/'Income Statement'!F6 -> 0.0081155093 | E34: ='Balance Sheet HISTORICAL'!G18/'Income Statement'!G6 -> 0.0075247602 | F34: ='Balance Sheet HISTORICAL'!H18/'Income Statement'!H6 -> 0.0075327743 | G34: ='Balance Sheet HISTORICAL'!I18/'Income Statement'!I6 -> 0.0091261157 | H34: ='Balance Sheet HISTORICAL'!J18/'Income Statement'!J6 -> 0.01238248 | I34: ='Balance Sheet HISTORICAL'!K18/'Income Statement'!K6 -> 0.018642304 | ... K34: ='Balance Sheet HISTORICAL'!M18/'Income Statement'!M6 -> 0.02506786 | M34: =AVERAGE(B34:K34) -> 0.013043215 | N34: =AVERAGE(G34:K34) -> 0.018052174 | O34: =AVERAGE(I34:K34) -> 0.022917425 | Q34: 0.025 | S34: Pre-Covid avg. is 0.8%; Covid to today avg. is 2.3%%; flat last 2 years so, stuck with that, 2.5% | T34: =Q34 -> 0.025 | U34: =T34 -> 0.025 | V34: =U34 -> 0.025 | W34: =V34 -> 0.025 | X34: =W34 -> 0.025
A36: Balance Sheet (NON-Debt Current Liabilities)
A37: Accounts payable as % of COGS | B37: ='Balance Sheet HISTORICAL'!D22/'Income Statement'!D7 -> 0.097402872 | C37: ='Balance Sheet HISTORICAL'!E22/'Income Statement'!E7 -> 0.1137841 | D37: ='Balance Sheet HISTORICAL'!F22/'Income Statement'!F7 -> 0.12718186 | E37: ='Balance Sheet HISTORICAL'!G22/'Income Statement'!G7 -> 0.1059953 | F37: ='Balance Sheet HISTORICAL'!H22/'Income Statement'!H7 -> 0.099587228 | G37: ='Balance Sheet HISTORICAL'!I22/'Income Statement'!I7 -> 0.11898837 | H37: ='Balance Sheet HISTORICAL'!J22/'Income Statement'!J7 -> 0.15158531 | I37: ='Balance Sheet HISTORICAL'!K22/'Income Statement'!K7 -> 0.12656952 | ... K37: ='Balance Sheet HISTORICAL'!M22/'Income Statement'!M7 -> 0.13302588 | M37: =AVERAGE(B37:K37) -> 0.11933537 | N37: =AVERAGE(G37:K37) -> 0.12988047 | O37: =AVERAGE(I37:K37) -> 0.12627623 | Q37: 0.124 | S37: Pre-Covid avg. is 10.7%; Covid to today avg. is 12.4%; choppy overall, higher post Covid, went with 3-yr avg 12.4% | T37: =Q37 -> 0.124 | U37: =T37 -> 0.124 | V37: =U37 -> 0.124 | W37: =V37 -> 0.124 | X37: =W37 -> 0.124
A38: Accrued liabilities as % of sales | B38: ='Balance Sheet HISTORICAL'!D23/'Income Statement'!D6 -> 0.04019569 | C38: ='Balance Sheet HISTORICAL'!E23/'Income Statement'!E6 -> 0.041392807 | D38: ='Balance Sheet HISTORICAL'!F23/'Income Statement'!F6 -> 0.049925625 | E38: ='Balance Sheet HISTORICAL'!G23/'Income Statement'!G6 -> 0.064232176 | F38: ='Balance Sheet HISTORICAL'!H23/'Income Statement'!H6 -> 0.043729774 | G38: ='Balance Sheet HISTORICAL'!I23/'Income Statement'!I6 -> 0.053023515 | H38: ='Balance Sheet HISTORICAL'!J23/'Income Statement'!J6 -> 0.052566128 | I38: ='Balance Sheet HISTORICAL'!K23/'Income Statement'!K6 -> 0.05235149 | ... K38: ='Balance Sheet HISTORICAL'!M23/'Income Statement'!M6 -> 0.052953398 | M38: =AVERAGE(B38:K38) -> 0.050621001 | N38: =AVERAGE(G38:K38) -> 0.053346787 | O38: =AVERAGE(I38:K38) -> 0.053714765 | Q38: 0.053 | S38: Pre-Covid avg. is 4.8%; 5-yr avg is 5.3% and it has been 5.3% in 3 out of last 5 years so, went with that | T38: =Q38 -> 0.053 | U38: =T38 -> 0.053 | V38: =U38 -> 0.053 | W38: =V38 -> 0.053 | X38: =W38 -> 0.053
A39: Accrued payroll & related expenses as % of sales | B39: ='Balance Sheet HISTORICAL'!D24/'Income Statement'!D6 -> 0.035321962 | C39: ='Balance Sheet HISTORICAL'!E24/'Income Statement'!E6 -> 0.054813881 | D39: ='Balance Sheet HISTORICAL'!F24/'Income Statement'!F6 -> 0.037376546 | E39: ='Balance Sheet HISTORICAL'!G24/'Income Statement'!G6 -> 0.036284815 | F39: ='Balance Sheet HISTORICAL'!H24/'Income Statement'!H6 -> 0.036142672 | G39: ='Balance Sheet HISTORICAL'!I24/'Income Statement'!I6 -> 0.036149504 | H39: ='Balance Sheet HISTORICAL'!J24/'Income Statement'!J6 -> 0.052574323 | I39: ='Balance Sheet HISTORICAL'!K24/'Income Statement'!K6 -> 0.022325662 | ... K39: ='Balance Sheet HISTORICAL'!M24/'Income Statement'!M6 -> 0.044119365 | M39: =AVERAGE(B39:K39) -> 0.038623361 | N39: =AVERAGE(G39:K39) -> 0.037258748 | O39: =AVERAGE(I39:K39) -> 0.032523304 | Q39: 0.04 | S39: Close to 4% long-term, recent upward trend, went with 4.0% | T39: =Q39 -> 0.04 | U39: =T39 -> 0.04 | V39: =U39 -> 0.04 | W39: =V39 -> 0.04 | X39: =W39 -> 0.04
A40: Income taxes payable as % of sales | B40: ='Balance Sheet HISTORICAL'!D27/'Income Statement'!D6 -> 0.0060478646 | C40: ='Balance Sheet HISTORICAL'!E27/'Income Statement'!E6 -> 0.0088817086 | D40: ='Balance Sheet HISTORICAL'!F27/'Income Statement'!F6 -> 0.0034322718 | E40: ='Balance Sheet HISTORICAL'!G27/'Income Statement'!G6 -> 0.0052017292 | F40: ='Balance Sheet HISTORICAL'!H27/'Income Statement'!H6 -> 0.0019936223 | G40: ='Balance Sheet HISTORICAL'!I27/'Income Statement'!I6 -> 0.0029694148 | H40: ='Balance Sheet HISTORICAL'!J27/'Income Statement'!J6 -> 0.0006494451 | I40: ='Balance Sheet HISTORICAL'!K27/'Income Statement'!K6 -> 9.8299988e-05 | ... K40: ='Balance Sheet HISTORICAL'!M27/'Income Statement'!M6 -> 0.0026314141 | M40: =AVERAGE(B40:K40) -> 0.0032825259 | N40: =AVERAGE(G40:K40) -> 0.0014536126 | O40: =AVERAGE(I40:K40) -> 0.001216401 | Q40: 0.001 | S40: Higher Pre vs. Post Covid, lower recently, 3 and 5-yr avg are the same so, went with 0.1% | T40: =Q40 -> 0.001 | U40: =T40 -> 0.001 | V40: =U40 -> 0.001 | W40: =V40 -> 0.001 | X40: =W40 -> 0.001
A42: Balance Sheet (NON-Debt Non-Current Liabilities)
A43: Deferred tax liabilities, net (ACTUAL) | B43: ='Balance Sheet HISTORICAL'!D31 -> 23145 | C43: ='Balance Sheet HISTORICAL'!E31 -> 16365 | D43: ='Balance Sheet HISTORICAL'!F31 -> 18949 | E43: ='Balance Sheet HISTORICAL'!G31 -> 11050 | F43: ='Balance Sheet HISTORICAL'!H31 -> 11688 | G43: ='Balance Sheet HISTORICAL'!I31 -> 11291 | H43: ='Balance Sheet HISTORICAL'!J31 -> 10401 | I43: ='Balance Sheet HISTORICAL'!K31 -> 10528 | ... K43: ='Balance Sheet HISTORICAL'!M31 -> 9066 | M43: =NA() -> #N/A | N43: =NA() -> #N/A | O43: =NA() -> #N/A | Q43: =K43 -> 9066 | S43: KEEP FLAT (SAME) = NO Cash Flow | T43: =Q43 -> 9066 | U43: =T43 -> 9066 | V43: =U43 -> 9066 | W43: =V43 -> 9066 | X43: =W43 -> 9066
A44: Long-term operating lease liabilities (ACTUAL) | B44: ='Balance Sheet HISTORICAL'!D32 -> 0 | C44: ='Balance Sheet HISTORICAL'!E32 -> 0 | D44: ='Balance Sheet HISTORICAL'!F32 -> 0 | E44: ='Balance Sheet HISTORICAL'!G32 -> 0 | F44: ='Balance Sheet HISTORICAL'!H32 -> 0 | G44: ='Balance Sheet HISTORICAL'!I32 -> 6520 | H44: ='Balance Sheet HISTORICAL'!J32 -> 7062 | I44: ='Balance Sheet HISTORICAL'!K32 -> 5999 | ... K44: ='Balance Sheet HISTORICAL'!M32 -> 5904 | M44: =NA() -> #N/A | N44: =NA() -> #N/A | O44: =NA() -> #N/A | Q44: =K44 -> 5904 | S44: KEEP FLAT (SAME) = NO Cash Flow | T44: =Q44 -> 5904 | U44: =T44 -> 5904 | V44: =U44 -> 5904 | W44: =V44 -> 5904 | X44: =W44 -> 5904
A45: Other long-term liabilities as % of sales | B45: ='Balance Sheet HISTORICAL'!D33/'Income Statement'!D6 -> 0.0060346423 | C45: ='Balance Sheet HISTORICAL'!E33/'Income Statement'!E6 -> 0.0058160612 | D45: ='Balance Sheet HISTORICAL'!F33/'Income Statement'!F6 -> 0.0051457796 | E45: ='Balance Sheet HISTORICAL'!G33/'Income Statement'!G6 -> 0.0044477844 | F45: ='Balance Sheet HISTORICAL'!H33/'Income Statement'!H6 -> 0.02524625 | G45: ='Balance Sheet HISTORICAL'!I33/'Income Statement'!I6 -> 0.027659866 | H45: ='Balance Sheet HISTORICAL'!J33/'Income Statement'!J6 -> 0.023523434 | I45: ='Balance Sheet HISTORICAL'!K33/'Income Statement'!K6 -> 0.021558537 | ... K45: ='Balance Sheet HISTORICAL'!M33/'Income Statement'!M6 -> 0.023818192 | M45: =AVERAGE(B45:K45) -> 0.016757047 | N45: =AVERAGE(G45:K45) -> 0.02417599 | O45: =AVERAGE(I45:K45) -> 0.023232217 | Q45: 0.024 | S45: Noticeable change 2018-2019, higher since, 2.4% 3 out of last 5 years, went with 5-yr avg of 2.4% | T45: =Q45 -> 0.024 | U45: =T45 -> 0.024 | V45: =U45 -> 0.024 | W45: =V45 -> 0.024 | X45: =W45 -> 0.024
A47: Shareholders' equity
...

Sheet Debt
A1: WD-40 Debt Schedule
A2: (USD in thousands, except per share data)
B4: Historical | E4: Projected
B5: 44804 | C5: 45169 | D5: 45535 | E5: 45900 | F5: 46265 | G5: 46630 | H5: 46996 | I5: 47361
A6: SHORT-TERM DEBT
A7: NEW REVOLVER | D7: 0 | E7: ='Balance Sheet PROJECTED'!N27 -> 0 | F7: ='Balance Sheet PROJECTED'!O27 -> 0 | G7: ='Balance Sheet PROJECTED'!P27 -> 0 | H7: ='Balance Sheet PROJECTED'!Q27 -> 0 | I7: ='Balance Sheet PROJECTED'!R27 -> 0
A9: Interest Rate | E9: =Assumptions!T54 -> 0.064 | F9: =Assumptions!U54 -> 0.064 | G9: =Assumptions!V54 -> 0.064 | H9: =Assumptions!W54 -> 0.064 | I9: =Assumptions!X54 -> 0.064
A11: Average Balance | E11: =AVERAGE(D7:E7) -> 0 | F11: =AVERAGE(E7:F7) -> 0 | G11: =AVERAGE(F7:G7) -> 0 | H11: =AVERAGE(G7:H7) -> 0 | I11: =AVERAGE(H7:I7) -> 0
A12: Interest Expense | E12: =E9*E11 -> 0 | F12: =F9*F11 -> 0 | G12: =G9*G11 -> 0 | H12: =H9*H11 -> 0 | I12: =I9*I11 -> 0
A14: LONG-TERM DEBT
A15: OLD REVOLVER (Beginning) | E15: =D17 -> 27836 | F15: =E17 -> 22268.8 | G15: =F17 -> 16701.6 | H15: =G17 -> 11134.4 | I15: =H17 -> 5567.2
A16: Paydown (5 years, 4/30/29) | E16: =$D$17/5 -> 5567.2 | F16: =$D$17/5 -> 5567.2 | G16: =$D$17/5 -> 5567.2 | H16: =$D$17/5 -> 5567.2 | I16: =$D$17/5 -> 5567.2
A17: OLD REVOLVER (Ending) | D17: ='Balance Sheet PROJECTED'!M30 -> 27836 | E17: =E15-E16 -> 22268.8 | F17: =F15-F16 -> 16701.6 | G17: =G15-G16 -> 11134.4 | H17: =H15-H16 -> 5567.2 | I17: =I15-I16 -> 0
A19: Interest Rate | E19: =Assumptions!T54 -> 0.064 | F19: =Assumptions!U54 -> 0.064 | G19: =Assumptions!V54 -> 0.064 | H19: =Assumptions!W54 -> 0.064 | I19: =Assumptions!X54 -> 0.064
A21: Average Balance | E21: =AVERAGE(D17:E17) -> 25052.4 | F21: =AVERAGE(E17:F17) -> 19485.2 | G21: =AVERAGE(F17:G17) -> 13918 | H21: =AVERAGE(G17:H17) -> 8350.8 | I21: =AVERAGE(H17:I17) -> 2783.6
A22: Interest Expense | E22: =E19*E21 -> 1603.3536 | F22: =F19*F21 -> 1247.0528 | G22: =G19*G21 -> 890.752 | H22: =H19*H21 -> 534.4512 | I22: =I19*I21 -> 178.1504
A24: Series A Notes Beginning | E24: =D26 -> 14800 | F24: =E26 -> 14000 | G24: =F26 -> 13200 | H24: =G26 -> 12400 | I24: =H26 -> 11600
A25: Paydown (11/15/2032) | E25: 800 | F25: 800 | G25: 800 | H25: 800 | I25: 800
A26: Series A Notes Ending | D26: ='Balance Sheet PROJECTED'!M31 -> 14800 | E26: =E24-E25 -> 14000 | F26: =F24-F25 -> 13200 | G26: =G24-G25 -> 12400 | H26: =H24-H25 -> 11600 | I26: =I24-I25 -> 10800
A28: Interest Rate | E28: =Assumptions!T55 -> 0.0339 | F28: =Assumptions!U55 -> 0.0339 | G28: =Assumptions!V55 -> 0.0339 | H28: =Assumptions!W55 -> 0.0339 | I28: =Assumptions!X55 -> 0.0339
A30: Average Balance | E30: =AVERAGE(D26:E26) -> 14400 | F30: =AVERAGE(E26:F26) -> 13600 | G30: =AVERAGE(F26:G26) -> 12800 | H30: =AVERAGE(G26:H26) -> 12000 | I30: =AVERAGE(H26:I26) -> 11200
A31: Interest Expense | E31: =E28*E30 -> 488.16 | F31: =F28*F30 -> 461.04 | G31: =G28*G30 -> 433.92 | H31: =H28*H30 -> 406.8 | I31: =I28*I30 -> 379.68
A33: Series B Notes Beginning | E33: =D35 -> 26000 | F33: =E35 -> 26000 | G33: =F35 -> 26000 | H33: =G35 -> 26000 | I33: =H35 -> 0
A34: Paydown (11/15/2027) | E34: 0 | F34: 0 | G34: 0 | H34: =H33 -> 26000 | I34: 0
A35: Series B Notes Ending | D35: ='Balance Sheet PROJECTED'!M32 -> 26000 | E35: =E33-E34 -> 26000 | F35: =F33-F34 -> 26000 | G35: =G33-G34 -> 26000 | H35: =H33-H34 -> 0 | I35: =I33-I34 -> 0
A37: Interest Rate | E37: =Assumptions!T56 -> 0.025 | F37: =Assumptions!U56 -> 0.025 | G37: =Assumptions!V56 -> 0.025 | H37: =Assumptions!W56 -> 0.025 | I37: =Assumptions!X56 -> 0.025
A39: Average Balance | E39: =AVERAGE(D35:E35) -> 26000 | F39: =AVERAGE(E35:F35) -> 26000 | G39: =AVERAGE(F35:G35) -> 26000 | H39: =AVERAGE(G35:H35) -> 13000 | I39: =AVERAGE(H35:I35) -> 0
A40: Interest Expense | E40: =E37*E39 -> 650 | F40: =F37*F39 -> 650 | G40: =G37*G39 -> 650 | H40: =H37*H39 -> 325 | I40: =I37*I39 -> 0
A42: Series C Notes Beginning | E42: =D44 -> 26000 | F42: =E44 -> 26000 | G42: =F44 -> 26000 | H42: =G44 -> 26000 | I42: =H44 -> 26000
A43: Paydown (11/15/2030) | E43: 0 | F43: 0 | G43: 0 | H43: 0 | I43: 0
A44: Series C Notes Ending | D44: ='Balance Sheet PROJECTED'!M33 -> 26000 | E44: =E42-E43 -> 26000 | F44: =F42-F43 -> 26000 | G44: =G42-G43 -> 26000 | H44: =H42-H43 -> 26000 | I44: =I42-I43 -> 26000
A46: Interest Rate | E46: =Assumptions!T57 -> 0.0269 | F46: =Assumptions!U57 -> 0.0269 | G46: =Assumptions!V57 -> 0.0269 | H46: =Assumptions!W57 -> 0.0269 | I46: =Assumptions!X57 -> 0.0269
A48: Average Balance | E48: =AVERAGE(D44:E44) -> 26000 | F48: =AVERAGE(E44:F44) -> 26000 | G48: =AVERAGE(F44:G44) -> 26000 | H48: =AVERAGE(G44:H44) -> 26000 | I48: =AVERAGE(H44:I44) -> 26000
A49: Interest Expense | E49: =E46*E48 -> 699.4 | F49: =F46*F48 -> 699.4 | G49: =G46*G48 -> 699.4 | H49: =H46*H48 -> 699.4 | I49: =I46*I48 -> 699.4
A51: Summary
A52: ST Debt | D52: =D7 -> 0 | E52: =E7 -> 0 | F52: =F7 -> 0 | G52: =G7 -> 0 | H52: =H7 -> 0 | I52: =I7 -> 0
A53: LT Debt | D53: =SUM(D17,D26,D35,D44) -> 94636 | E53: =SUM(E17,E26,E35,E44) -> 88268.8 | F53: =SUM(F17,F26,F35,F44) -> 81901.6 | G53: =SUM(G17,G26,G35,G44) -> 75534.4 | H53: =SUM(H17,H26,H35,H44) -> 43167.2 | I53: =SUM(I17,I26,I35,I44) -> 36800
A54: Total Debt | D54: =SUM(D52:D53) -> 94636 | E54: =SUM(E52:E53) -> 88268.8 | F54: =SUM(F52:F53) -> 81901.6 | G54: =SUM(G52:G53) -> 75534.4 | H54: =SUM(H52:H53) -> 43167.2 | I54: =SUM(I52:I53) -> 36800
A56: Interest Expense Summary
A57: ST Debt Interest | E57: =E12 -> 0 | F57: =F12 -> 0 | G57: =G12 -> 0 | H57: =H12 -> 0 | I57: =I12 -> 0
...

Sheet Calcs
A1: WD-40 Calculations
B2: (USD in thousands, except per share data) | K2: Historical | N2: Projected
C3: 41882 | D3: 42247 | E3: 42613 | F3: 42978 | G3: 43343 | H3: 43708 | I3: 44074 | J3: 44439 | K3: 44804 | L3: 45169 | M3: 45535 | N3: 45900 | O3: 46265 | P3: 46630 | Q3: 46996 | R3: 47361
A4: Retained Earnings
B5: Beginning Balance (Previous Ending) | D5: =C9 -> 237596 | E5: =D9 -> 260683 | F5: =E9 -> 289642 | G5: =F9 -> 315764 | H5: =G9 -> 351266 | I5: =H9 -> 374060 | J5: =I9 -> 398731 | K5: =J9 -> 430735 | ... R5: =Q9 -> 667138.5
B6: Net Income | D6: ='Income Statement'!D20 -> 44807 | E6: ='Income Statement'!E20 -> 52628 | F6: ='Income Statement'!F20 -> 52930 | G6: ='Income Statement'!G20 -> 65215 | H6: ='Income Statement'!H20 -> 55908 | I6: ='Income Statement'!I20 -> 60710 | J6: ='Income Statement'!J20 -> 70229 | K6: ='Income Statement'!K20 -> 67329 | ... R6: ='Income Statement'!R20 -> 115573.96
B7: Dividends Paid (from CFS) | D7: 21720 | E7: 23669 | F7: 26808 | G7: 29585 | H7: 32889 | I7: 36039 | J7: 38225 | K7: 41988 | L7: 44581 | M7: 47201 | N7: =Assumptions!T19*Calcs!N6 -> 47072.172 | O7: =Assumptions!U19*Calcs!O6 -> 50978.463 | P7: =Assumptions!V19*Calcs!P6 -> 55187.325 | Q7: =Assumptions!W19*Calcs!Q6 -> 59571.584 | R7: =Assumptions!X19*Calcs!R6 -> 64721.416
B8: Cumulative effect of change in accounting principle | D8: 0 | E8: 0 | F8: 0 | G8: -128 | H8: -225 | I8: 0 | J8: 0 | K8: 0 | L8: 0 | M8: 0 | N8: =M8 -> 0 | O8: =N8 -> 0 | P8: =O8 -> 0 | Q8: =P8 -> 0 | R8: =Q8 -> 0
B9: Ending Balance (CALCULATED) | C9: ='Balance Sheet HISTORICAL'!$C$39 -> 237596 | D9: =D5+D6-D7+D8 -> 260683 | E9: =E5+E6-E7+E8 -> 289642 | F9: =F5+F6-F7+F8 -> 315764 | G9: =G5+G6-G7+G8 -> 351266 | H9: =H5+H6-H7+H8 -> 374060 | I9: =I5+I6-I7+I8 -> 398731 | J9: =J5+J6-J7+J8 -> 430735 | K9: =K5+K6-K7+K8 -> 456076 | ... R9: =R5+R6-R7+R8 -> 717991.04
B10: Check (Actual from Balance Sheet) | D10: ='Balance Sheet HISTORICAL'!D39 -> 260683 | E10: ='Balance Sheet HISTORICAL'!E39 -> 289642 | F10: ='Balance Sheet HISTORICAL'!F39 -> 315764 | G10: ='Balance Sheet HISTORICAL'!G39 -> 351266 | H10: ='Balance Sheet HISTORICAL'!H39 -> 374060 | I10: ='Balance Sheet HISTORICAL'!I39 -> 398731 | J10: ='Balance Sheet HISTORICAL'!J39 -> 430735 | K10: ='Balance Sheet HISTORICAL'!K39 -> 456076 | ... M10: ='Balance Sheet HISTORICAL'!M39 -> 499931
D11: =D9-D10 -> 0 | E11: =E9-E10 -> 0 | F11: =F9-F10 -> 0 | G11: =G9-G10 -> 0 | H11: =H9-H10 -> 0 | I11: =I9-I10 -> 0 | J11: =J9-J10 -> 0 | K11: =K9-K10 -> 0 | ... M11: =M9-M10 -> 0
A12: Intangibles
B13: Beginning Balance (Previous Ending) | D13: =C16 -> 23671 | E13: =D16 -> 22961 | F13: =E16 -> 19191 | G13: =F16 -> 16244 | H13: =G16 -> 13513 | I13: =H16 -> 10652 | J13: =I16 -> 8633 | K13: =J16 -> 7244 | ... R13: =Q16 -> 610.83564
B14: NEW Intangibles | D14: =D16-D13+D15 -> 2329 | E14: =E16-E13+E15 -> -794 | F14: =F16-F13+F15 -> -68 | G14: =G16-G13+G15 -> 220 | H14: =H16-H13+H15 -> -155 | I14: =I16-I13+I15 -> 192 | J14: =J16-J13+J15 -> 60 | K14: =K16-K13+K15 -> -222 | ... M14: =M16-M13+M15 -> 2658 | N14: =Assumptions!T31 -> 0 | O14: =Assumptions!U31 -> 0 | P14: =Assumptions!V31 -> 0 | Q14: =Assumptions!W31 -> 0 | R14: =Assumptions!X31 -> 0
B15: Amortization | D15: ='Income Statement'!D13 -> 3039 | E15: ='Income Statement'!E13 -> 2976 | F15: ='Income Statement'!F13 -> 2879 | G15: ='Income Statement'!G13 -> 2951 | H15: ='Income Statement'!H13 -> 2706 | I15: ='Income Statement'!I13 -> 2211 | J15: ='Income Statement'!J13 -> 1449 | K15: ='Income Statement'!K13 -> 1434 | ... M15: ='Income Statement'!M13 -> 1106 | N15: =IF((Assumptions!T9*'Income Statement'!N6)>Calcs!N13,Calcs!N13,(Assumptions!T9*'Income Statement'!N6)) -> 1263.792 | O15: =IF((Assumptions!U9*'Income Statement'!O6)>Calcs!O13,Calcs!O13,(Assumptions!U9*'Income Statement'!O6)) -> 1352.2574 | P15: =IF((Assumptions!V9*'Income Statement'!P6)>Calcs!P13,Calcs!P13,(Assumptions!V9*'Income Statement'!P6)) -> 1446.9154 | Q15: =IF((Assumptions!W9*'Income Statement'!Q6)>Calcs!Q13,Calcs!Q13,(Assumptions!W9*'Income Statement'!Q6)) -> 1548.1995 | R15: =IF((Assumptions!X9*'Income Statement'!R6)>Calcs!R13,Calcs!R13,(Assumptions!X9*'Income Statement'!R6)) -> 610.83564
B16: Ending Balance (Actual from B/S) | C16: ='Balance Sheet HISTORICAL'!C15 -> 23671 | D16: ='Balance Sheet HISTORICAL'!D15 -> 22961 | E16: ='Balance Sheet HISTORICAL'!E15 -> 19191 | F16: ='Balance Sheet HISTORICAL'!F15 -> 16244 | G16: ='Balance Sheet HISTORICAL'!G15 -> 13513 | H16: ='Balance Sheet HISTORICAL'!H15 -> 10652 | I16: ='Balance Sheet HISTORICAL'!I15 -> 8633 | J16: ='Balance Sheet HISTORICAL'!J15 -> 7244 | ... M16: ='Balance Sheet HISTORICAL'!M15 -> 6222 | N16: =N13+N14-N15 -> 4958.208 | O16: =O13+O14-O15 -> 3605.9506 | P16: =P13+P14-P15 -> 2159.0352 | Q16: =Q13+Q14-Q15 -> 610.83564 | R16: =R13+R14-R15 -> 0
A18: PP&E (Property, Plant & Equipment)
B19: Beginning Balance (Previous Ending) | D19: =C22 -> 9702 | E19: =D22 -> 11376 | F19: =E22 -> 11545 | G19: =F22 -> 29439 | H19: =G22 -> 36357 | I19: =H22 -> 45076 | J19: =I22 -> 60759 | K19: =J22 -> 70145 | ... R19: =Q22 -> 79816.493
B20: Capital Expenditures (Actual from CFS) | D20: 5784 | E20: 4354 | F20: 20150 | G20: 12356 | H20: 13282 | I20: 19307 | J20: 15059 | K20: 8303 | L20: 6871 | M20: 4206 | N20: =Assumptions!T28*'Income Statement'!N6 -> 12637.92 | O20: =Assumptions!U28*'Income Statement'!O6 -> 13522.574 | P20: =Assumptions!V28*'Income Statement'!P6 -> 14469.154 | Q20: =Assumptions!W28*'Income Statement'!Q6 -> 15481.995 | R20: =Assumptions!X28*'Income Statement'!R6 -> 16565.735
B21: Depreciation (Calculated Below) | D21: =D26 -> 3425 | E21: =E26 -> 3489 | F21: =F26 -> 3890 | G21: =G26 -> 4849 | H21: =H26 -> 4887 | I21: =I26 -> 5490 | J21: =J26 -> 5570 | K21: =K26 -> 6860 | ... M21: =M26 -> 8350 | N21: =Assumptions!T29*'Income Statement'!N6 -> 8846.5439 | O21: =Assumptions!U29*'Income Statement'!O6 -> 9465.8019 | P21: =Assumptions!V29*'Income Statement'!P6 -> 10128.408 | Q21: =Assumptions!W29*'Income Statement'!Q6 -> 10837.397 | R21: =Assumptions!X29*'Income Statement'!R6 -> 11596.014
B22: Ending Balance (Actual from B/S) | C22: ='Balance Sheet HISTORICAL'!C13 -> 9702 | D22: ='Balance Sheet HISTORICAL'!D13 -> 11376 | E22: ='Balance Sheet HISTORICAL'!E13 -> 11545 | F22: ='Balance Sheet HISTORICAL'!F13 -> 29439 | G22: ='Balance Sheet HISTORICAL'!G13 -> 36357 | H22: ='Balance Sheet HISTORICAL'!H13 -> 45076 | I22: ='Balance Sheet HISTORICAL'!I13 -> 60759 | J22: ='Balance Sheet HISTORICAL'!J13 -> 70145 | ... M22: ='Balance Sheet HISTORICAL'!M13 -> 62983 | N22: =N19+N20-N21 -> 66774.376 | O22: =O19+O20-O21 -> 70831.148 | P22: =P19+P20-P21 -> 75171.895 | Q22: =Q19+Q20-Q21 -> 79816.493 | R22: =R19+R20-R21 -> 84786.214
B24: Depreciation & Amortization (from CFS) | C24: 5860 | D24: 6464 | E24: 6465 | F24: 6769 | G24: 7800 | H24: 7593 | I24: 7701 | J24: 7019 | K24: 8294 | L24: 8151 | M24: 9456
B25: Amortization of definite-lived intangible assets | C25: ='Income Statement'!C13 -> 2617 | D25: ='Income Statement'!D13 -> 3039 | E25: ='Income Statement'!E13 -> 2976 | F25: ='Income Statement'!F13 -> 2879 | G25: ='Income Statement'!G13 -> 2951 | H25: ='Income Statement'!H13 -> 2706 | I25: ='Income Statement'!I13 -> 2211 | J25: ='Income Statement'!J13 -> 1449 | ... M25: ='Income Statement'!M13 -> 1106
B26: Depreciation (D&A - A) | C26: =C24-C25 -> 3243 | D26: =D24-D25 -> 3425 | E26: =E24-E25 -> 3489 | F26: =F24-F25 -> 3890 | G26: =G24-G25 -> 4849 | H26: =H24-H25 -> 4887 | I26: =I24-I25 -> 5490 | J26: =J24-J25 -> 5570 | ... M26: =M24-M25 -> 8350
B28: Cost of products sold | C28: 184144 | D28: 177972 | E28: 166301 | F28: 166621 | G28: 183255 | H28: 191010 | I28: 185481 | J28: 224370 | K28: 264055 | L28: 263035 | M28: 275330
B29: Selling, general and administrative | C29: 108577 | D29: 108873 | E29: 117767 | F29: 114560 | G29: 121394 | H29: 123946 | I29: 121980 | J29: 145493 | K29: 138658 | L29: 154684 | M29: 183859
B30: Total Combined | C30: =SUM(C28:C29) -> 292721 | D30: =SUM(D28:D29) -> 286845 | E30: =SUM(E28:E29) -> 284068 | F30: =SUM(F28:F29) -> 281181 | G30: =SUM(G28:G29) -> 304649 | H30: =SUM(H28:H29) -> 314956 | I30: =SUM(I28:I29) -> 307461 | J30: =SUM(J28:J29) -> 369863 | ... M30: =SUM(M28:M29) -> 459189
B32: % COGS | C32: =C28/C$30 -> 0.62907683 | D32: =D28/D$30 -> 0.62044658 | E32: =E28/E$30 -> 0.58542673 | F32: =F28/F$30 -> 0.5925756 | G32: =G28/G$30 -> 0.60152832 | H32: =H28/H$30 -> 0.60646567 | I32: =I28/I$30 -> 0.60326676 | J32: =J28/J$30 -> 0.60663002 | ... M32: =M28/M$30 -> 0.5996006
B33: % SG&A | C33: =C29/C$30 -> 0.37092317 | D33: =D29/D$30 -> 0.37955342 | E33: =E29/E$30 -> 0.41457327 | F33: =F29/F$30 -> 0.4074244 | G33: =G29/G$30 -> 0.39847168 | H33: =H29/H$30 -> 0.39353433 | I33: =I29/I$30 -> 0.39673324 | J33: =J29/J$30 -> 0.39336998 | ... M33: =M29/M$30 -> 0.4003994
B35: Depreciation in COGS | C35: =C$26*C32 -> 2040.0962 | D35: =D$26*D32 -> 2125.0295 | E35: =E$26*E32 -> 2042.5539 | F35: =F$26*F32 -> 2305.1191 | G35: =G$26*G32 -> 2916.8108 | H35: =H$26*H32 -> 2963.7977 | I35: =I$26*I32 -> 3311.9345 | J35: =J$26*J32 -> 3378.9292 | ... M35: =M$26*M32 -> 5006.665
B36: Depreciation in SG&A | C36: =C$26*C33 -> 1202.9038 | D36: =D$26*D33 -> 1299.9705 | E36: =E$26*E33 -> 1446.4461 | F36: =F$26*F33 -> 1584.8809 | G36: =G$26*G33 -> 1932.1892 | H36: =H$26*H33 -> 1923.2023 | I36: =I$26*I33 -> 2178.0655 | J36: =J$26*J33 -> 2191.0708 | ... M36: =M$26*M33 -> 3343.335
B37: Total Depreciation | C37: =SUM(C35:C36) -> 3243 | D37: =SUM(D35:D36) -> 3425 | E37: =SUM(E35:E36) -> 3489 | F37: =SUM(F35:F36) -> 3890 | G37: =SUM(G35:G36) -> 4849 | H37: =SUM(H35:H36) -> 4887 | I37: =SUM(I35:I36) -> 5490 | J37: =SUM(J35:J36) -> 5570 | ... M37: =SUM(M35:M36) -> 8350
B39: Clean COGS | C39: =C28-C35 -> 182103.9 | D39: =D28-D35 -> 175846.97 | E39: =E28-E35 -> 164258.45 | F39: =F28-F35 -> 164315.88 | G39: =G28-G35 -> 180338.19 | H39: =H28-H35 -> 188046.2 | I39: =I28-I35 -> 182169.07 | J39: =J28-J35 -> 220991.07 | ... M39: =M28-M35 -> 270323.33
B40: Clean SG&A | C40: =C29-C36 -> 107374.1 | D40: =D29-D36 -> 107573.03 | E40: =E29-E36 -> 116320.55 | F40: =F29-F36 -> 112975.12 | G40: =G29-G36 -> 119461.81 | H40: =H29-H36 -> 122022.8 | I40: =I29-I36 -> 119801.93 | J40: =J29-J36 -> 143301.93 | ... M40: =M29-M36 -> 180515.67
A42: Operating Working Capital ((CA-Cash) - (CL - ST Debt))
B43: Trade and other accounts receivable, net | C43: ='Balance Sheet PROJECTED'!C8 -> 63618 | D43: ='Balance Sheet PROJECTED'!D8 -> 58750 | E43: ='Balance Sheet PROJECTED'!E8 -> 64680 | F43: ='Balance Sheet PROJECTED'!F8 -> 64259 | G43: ='Balance Sheet PROJECTED'!G8 -> 69025 | H43: ='Balance Sheet PROJECTED'!H8 -> 72864 | I43: ='Balance Sheet PROJECTED'!I8 -> 80672 | J43: ='Balance Sheet PROJECTED'!J8 -> 89558 | ... R43: ='Balance Sheet PROJECTED'!R8 -> 165657.35
B44: Inventories | C44: ='Balance Sheet PROJECTED'!C9 -> 34989 | D44: ='Balance Sheet PROJECTED'!D9 -> 32052 | E44: ='Balance Sheet PROJECTED'!E9 -> 31793 | F44: ='Balance Sheet PROJECTED'!F9 -> 35340 | G44: ='Balance Sheet PROJECTED'!G9 -> 36536 | H44: ='Balance Sheet PROJECTED'!H9 -> 40682 | I44: ='Balance Sheet PROJECTED'!I9 -> 41264 | J44: ='Balance Sheet PROJECTED'!J9 -> 55752 | ... R44: ='Balance Sheet PROJECTED'!R9 -> 96288.334
B45: Current deferred tax assets, net | C45: ='Balance Sheet PROJECTED'!C10 -> 5855 | D45: ='Balance Sheet PROJECTED'!D10 -> 5824 | E45: ='Balance Sheet PROJECTED'!E10 -> 0 | F45: ='Balance Sheet PROJECTED'!F10 -> 0 | G45: ='Balance Sheet PROJECTED'!G10 -> 0 | H45: ='Balance Sheet PROJECTED'!H10 -> 0 | I45: ='Balance Sheet PROJECTED'!I10 -> 0 | J45: ='Balance Sheet PROJECTED'!J10 -> 0 | ... R45: ='Balance Sheet PROJECTED'!R10 -> 0
B46: Other current assets | C46: ='Balance Sheet PROJECTED'!C11 -> 8339 | D46: ='Balance Sheet PROJECTED'!D11 -> 6127 | E46: ='Balance Sheet PROJECTED'!E11 -> 4475 | F46: ='Balance Sheet PROJECTED'!F11 -> 8007 | G46: ='Balance Sheet PROJECTED'!G11 -> 13337 | H46: ='Balance Sheet PROJECTED'!H11 -> 7216 | I46: ='Balance Sheet PROJECTED'!I11 -> 6756 | J46: ='Balance Sheet PROJECTED'!J11 -> 9948 | ... R46: ='Balance Sheet PROJECTED'!R11 -> 16565.735
B47: Total Operating Assets | C47: =SUM(C43:C46) -> 112801 | D47: =SUM(D43:D46) -> 102753 | E47: =SUM(E43:E46) -> 100948 | F47: =SUM(F43:F46) -> 107606 | G47: =SUM(G43:G46) -> 118898 | H47: =SUM(H43:H46) -> 120762 | I47: =SUM(I43:I46) -> 128692 | J47: =SUM(J43:J46) -> 155258 | ... R47: =SUM(R43:R46) -> 278511.42
...

Sheet Income Statement
A1: WD-40 Income Statement
B2: (USD in thousands, except per share data)
K3: Historical | N3: Projected
C4: 41882 | D4: 42247 | E4: 42613 | F4: 42978 | G4: 43343 | H4: 43708 | I4: 44074 | J4: 44439 | K4: 44804 | L4: 45169 | M4: 45535 | N4: 45900 | O4: 46265 | P4: 46630 | Q4: 46996 | R4: 47361
B6: Net sales | C6: 382997 | D6: 378150 | E6: 380670 | F6: 380506 | G6: 408518 | H6: 423350 | I6: 408498 | J6: 488109 | K6: 518820 | L6: 537255 | M6: 590557 | N6: =(1+Assumptions!T5)*'Income Statement'!M6 -> 631895.99 | O6: =(1+Assumptions!U5)*'Income Statement'!N6 -> 676128.71 | P6: =(1+Assumptions!V5)*'Income Statement'!O6 -> 723457.72 | Q6: =(1+Assumptions!W5)*'Income Statement'!P6 -> 774099.76 | R6: =(1+Assumptions!X5)*'Income Statement'!Q6 -> 828286.74
B7: Clean COGS | C7: =Calcs!C39 -> 182103.9 | D7: =Calcs!D39 -> 175846.97 | E7: =Calcs!E39 -> 164258.45 | F7: =Calcs!F39 -> 164315.88 | G7: =Calcs!G39 -> 180338.19 | H7: =Calcs!H39 -> 188046.2 | I7: =Calcs!I39 -> 182169.07 | J7: =Calcs!J39 -> 220991.07 | ... M7: =Calcs!M39 -> 270323.33 | N7: =Assumptions!T6*'Income Statement'!N6 -> 293831.64 | O7: =Assumptions!U6*'Income Statement'!O6 -> 314399.85 | P7: =Assumptions!V6*'Income Statement'!P6 -> 336407.84 | Q7: =Assumptions!W6*'Income Statement'!Q6 -> 359956.39 | R7: =Assumptions!X6*'Income Statement'!R6 -> 385153.34
A8: * | B8: Gross profit | C8: =C6-C7 -> 200893.1 | D8: =D6-D7 -> 202303.03 | E8: =E6-E7 -> 216411.55 | F8: =F6-F7 -> 216190.12 | G8: =G6-G7 -> 228179.81 | H8: =H6-H7 -> 235303.8 | I8: =I6-I7 -> 226328.93 | J8: =J6-J7 -> 267117.93 | ... R8: =R6-R7 -> 443133.41
B9: Clean SG&A | C9: =Calcs!C40 -> 107374.1 | D9: =Calcs!D40 -> 107573.03 | E9: =Calcs!E40 -> 116320.55 | F9: =Calcs!F40 -> 112975.12 | G9: =Calcs!G40 -> 119461.81 | H9: =Calcs!H40 -> 122022.8 | I9: =Calcs!I40 -> 119801.93 | J9: =Calcs!J40 -> 143301.93 | ... M9: =Calcs!M40 -> 180515.67 | N9: =Assumptions!T7*'Income Statement'!N6 -> 180090.36 | O9: =Assumptions!U7*'Income Statement'!O6 -> 192696.68 | P9: =Assumptions!V7*'Income Statement'!P6 -> 206185.45 | Q9: =Assumptions!W7*'Income Statement'!Q6 -> 220618.43 | R9: =Assumptions!X7*'Income Statement'!R6 -> 236061.72
B10: Advertising and sales promotion | C10: 23922 | D10: 22876 | E10: 22278 | F10: 20537 | G10: 22314 | H10: 23306 | I10: 21606 | J10: 27956 | K10: 27343 | L10: 28807 | M10: 33911 | N10: =Assumptions!T8*'Income Statement'!N6 -> 37913.759 | O10: =Assumptions!U8*'Income Statement'!O6 -> 40567.723 | P10: =Assumptions!V8*'Income Statement'!P6 -> 43407.463 | Q10: =Assumptions!W8*'Income Statement'!Q6 -> 46445.986 | R10: =Assumptions!X8*'Income Statement'!R6 -> 49697.205
B11: EBITDA | C11: =C8-SUM(C9:C10) -> 69597 | D11: =D8-SUM(D9:D10) -> 71854 | E11: =E8-SUM(E9:E10) -> 77813 | F11: =F8-SUM(F9:F10) -> 82678 | G11: =G8-SUM(G9:G10) -> 86404 | H11: =H8-SUM(H9:H10) -> 89975 | I11: =I8-SUM(I9:I10) -> 84921 | J11: =J8-SUM(J9:J10) -> 95860 | ... R11: =R8-SUM(R9:R10) -> 157374.48
B12: Depreciation | C12: =Calcs!C26 -> 3243 | D12: =Calcs!D26 -> 3425 | E12: =Calcs!E26 -> 3489 | F12: =Calcs!F26 -> 3890 | G12: =Calcs!G26 -> 4849 | H12: =Calcs!H26 -> 4887 | I12: =Calcs!I26 -> 5490 | J12: =Calcs!J26 -> 5570 | ... M12: =Calcs!M26 -> 8350 | N12: =Calcs!N21 -> 8846.5439 | O12: =Calcs!O21 -> 9465.8019 | P12: =Calcs!P21 -> 10128.408 | Q12: =Calcs!Q21 -> 10837.397 | R12: =Calcs!R21 -> 11596.014
B13: Amortization of definite-lived intangible assets | C13: 2617 | D13: 3039 | E13: 2976 | F13: 2879 | G13: 2951 | H13: 2706 | I13: 2211 | J13: 1449 | K13: 1434 | L13: 1005 | M13: 1106 | N13: =Calcs!N15 -> 1263.792 | O13: =Calcs!O15 -> 1352.2574 | P13: =Calcs!P15 -> 1446.9154 | Q13: =Calcs!Q15 -> 1548.1995 | R13: =Calcs!R15 -> 610.83564
A14: * | B14: Income from operations (EBIT) | C14: =C11-SUM(C12:C13) -> 63737 | D14: =D11-SUM(D12:D13) -> 65390 | E14: =E11-SUM(E12:E13) -> 71348 | F14: =F11-SUM(F12:F13) -> 75909 | G14: =G11-SUM(G12:G13) -> 78604 | H14: =H11-SUM(H12:H13) -> 82382 | I14: =I11-SUM(I12:I13) -> 77220 | J14: =J11-SUM(J12:J13) -> 88841 | ... R14: =R11-SUM(R12:R13) -> 145167.63
B15: Interest income | C15: 596 | D15: 584 | E15: 683 | F15: 508 | G15: 454 | H15: 155 | I15: 93 | J15: 81 | K15: 102 | L15: 231 | M15: 474 | N15: =Debt!E69 -> 2656.5305 | O15: =Debt!F69 -> 3635.7325 | P15: =Debt!G69 -> 4777.8769 | Q15: =Debt!H69 -> 5425.317 | R15: =Debt!I69 -> 6185.6468
B16: Interest expense | C16: -1002 | D16: -1205 | E16: -1703 | F16: -2582 | G16: -4219 | H16: -2541 | I16: -2439 | J16: -2395 | K16: -2742 | L16: -5614 | M16: -4287 | N16: =-Debt!E59 -> -3440.9136 | O16: =-Debt!F59 -> -3057.4928 | P16: =-Debt!G59 -> -2674.072 | Q16: =-Debt!H59 -> -1965.6512 | R16: =-Debt!I59 -> -1257.2304
